<?xml version='1.0' encoding='utf-8'?>
<robot name="robot">
  <link name="base_footprint"><inertial><origin xyz="0 0 0" rpy="0 0 0" /><mass value="5e-07" /><inertia ixx="5e-10" ixy="0" ixz="0" iyy="5e-10" iyz="0" izz="5e-10" /></inertial></link>
  <joint name="base_joint" type="fixed">
    <parent link="base_footprint" />
    <child link="base_link" />
    <origin xyz="0 0 0" rpy="1.5708 0 1.5708" />
  </joint>
  <link name="base_link">
    <visual>
      <origin xyz="0 0 0" rpy="0 0 0" />
      <geometry>
        <mesh filename="package://robot_description/meshes/baselink.stl" scale="0.001 0.001 0.001" />
      </geometry>
      <material name="base_link-material">
        <color rgba="0.08228270712149792 0.019382360952473074 0.2541520943200296 1" />
      </material>
    </visual>
    <collision>
      <origin xyz="0 0 0" rpy="0 0 0" />
      <geometry>
        <mesh filename="package://robot_description/meshes/baselink.stl" scale="0.001 0.001 0.001" />
      </geometry>
    </collision>
    <inertial>
      <origin xyz="0 0 0" rpy="0 0 0" />
      <mass value="0.0005" />
      <inertia ixx="2e-06" ixy="0" ixz="0" iyy="2e-06" iyz="0" izz="2e-06" />
    </inertial>
  </link>
  <joint name="base_link_to_LINK1A" type="revolute">
    <parent link="base_link" />
    <child link="LINK1A" />
    <origin xyz="-0.029 0.042 0.016" rpy="0 0 0" />
    <axis xyz="-0.00164931 -0.00672792 0.0997598" />
    <limit effort="10" lower="-0.4" upper="0.6" velocity="0.5" />  </joint>
  <link name="LINK1A">
    <visual>
      <origin xyz="0.03 -0.041 -0.016" rpy="0 0 0" />
      <geometry>
        <mesh filename="package://robot_description/meshes/link1a 2.stl" scale="1 1 1" />
      </geometry>
      <material name="cube1-material">
        <color rgba="0.10702310296918527 0.02121901037134225 0.9734452903978066 1" />
      </material>
    </visual>
    <collision>
      <origin xyz="0.03 -0.041 -0.016" rpy="0 0 0" />
      <geometry>
        <mesh filename="package://robot_description/meshes/link1a 2.stl" scale="1 1 1" />
      </geometry>
    </collision>
    <inertial>
      <origin xyz="0.03 -0.041 -0.016" rpy="0 0 0" />
      <mass value="0.0005" />
      <inertia ixx="2e-06" ixy="0" ixz="0" iyy="2e-06" iyz="0" izz="2e-06" />
    </inertial>
  </link>
  <joint name="LINK1A_to_LINK1B" type="revolute">
    <parent link="LINK1A" />
    <child link="LINK1B" />
    <origin xyz="-0.0286653 0.058989 0" rpy="0 0 0" />
    <axis xyz="0 0 0.1" />
    <limit effort="10" lower="-1" upper="1" velocity="0.5" />  </joint>
  <link name="LINK1B">
    <visual>
      <origin xyz="0.065 -0.100989 -0.015" rpy="0 0 0" />
      <geometry>
        <mesh filename="package://robot_description/meshes/link1b.stl" scale="1 1 1" />
      </geometry>
      <material name="cube2-material">
        <color rgba="0.10702310296918527 0.5647115056965487 0.5394794890033748 1" />
      </material>
    </visual>
    <collision>
      <origin xyz="0.101 -0.142989 -0.03" rpy="0 0 0" />
      <geometry>
        <mesh filename="package://robot_description/meshes/link1b.stl" scale="1 1 1" />
      </geometry>
    </collision>
    <inertial>
      <origin xyz="0.101 -0.142989 -0.03" rpy="0 0 0" />
      <mass value="0.0005" />
      <inertia ixx="2e-06" ixy="0" ixz="0" iyy="2e-06" iyz="0" izz="2e-06" />
    </inertial>
  </link>
  <joint name="base_link_to_LINK2A" type="revolute">
    <parent link="base_link" />
    <child link="LINK2A" />
    <origin xyz="0.029 0.042 0.016" rpy="0 0 0" />
    <axis xyz="0 0 0.1" />
    <limit effort="10" lower="-1" upper="0.4" velocity="0.5" />  </joint>
  <link name="LINK2A">
    <visual>
      <origin xyz="-0.029 -0.04 -0.016" rpy="0 0 0" />
      <geometry>
        <mesh filename="package://robot_description/meshes/link2a.stl" scale="1 1 1" />
      </geometry>
      <material name="cube3-material">
        <color rgba="0.4286904966038916 0.0069954101845983935 0.6307571363387763 1" />
      </material>
    </visual>
    <collision>
      <origin xyz="-0.029 -0.04 -0.016" rpy="0 0 0" />
      <geometry>
        <mesh filename="package://robot_description/meshes/link2a.stl" scale="1 1 1" />
      </geometry>
    </collision>
    <inertial>
      <origin xyz="-0.029 -0.04 -0.016" rpy="0 0 0" />
      <mass value="0.0005" />
      <inertia ixx="2e-06" ixy="0" ixz="0" iyy="2e-06" iyz="0" izz="2e-06" />
    </inertial>
  </link>
  <joint name="LINK2A_to_LINK2B" type="revolute">
    <parent link="LINK2A" />
    <child link="LINK2B" />
    <origin xyz="0.029 0.059 0" rpy="0 0 0" />
    <axis xyz="0 0 0.1" />
    <limit effort="10" lower="-1" upper="1" velocity="0.5" />  </joint>
  <link name="LINK2B">
    <visual>
      <origin xyz="-0.0652158 -0.100771 -0.0151186" rpy="0 0 0" />
      <geometry>
        <mesh filename="package://robot_description/meshes/link2b.stl" scale="1 1 1" />
      </geometry>
      <material name="cube4-material">
        <color rgba="0.8148465722120952 0.4452011945063733 0.7011018919268015 1" />
      </material>
    </visual>
    <collision>
      <origin xyz="-0.0652158 -0.100771 -0.0166186" rpy="0 0 0" />
      <geometry>
        <mesh filename="package://robot_description/meshes/link2b.stl" scale="1 1 1" />
      </geometry>
    </collision>
    <inertial>
      <origin xyz="-0.0652158 -0.100771 -0.0166186" rpy="0 0 0" />
      <mass value="0.0005" />
      <inertia ixx="2e-06" ixy="0" ixz="0" iyy="2e-06" iyz="0" izz="2e-06" />
    </inertial>
  </link>
</robot>